<!DOCTYPE html>
<html lang="en">

<head>
    <meta charset="UTF-8">
    <meta name="viewport" content="width=device-width, initial-scale=1.0">
    <title>Error Handling</title>
    <style>
        body {
            background: #000;
            font-size: 18px;
            color: #fff;
            font-family: Arial, Helvetica, sans-serif;
        }
    </style>
</head>

<body>
    <h1>Error Handling</h1>

    <form id="submit">
        <input type="text" name="text" placeholder="Empty Submit">
        <button type="submit">Submit</button>
    </form>

    <script>

        // Write a function that intentionally throws an error and use a try-catch block to handle the error and log an appropriate message to the console.

        function throwError() {
            throw new Error("This is an intentional error!");
        }

        try {
            throwError();
        } catch (error) {
            console.error("An error occurred: " + error.message);
        }







        // Create a function that divides two numbers and throws an error if the denominator is zero. Use a try-catch block to handle this error.

        function divideNumbers(numerator, denominator) {
            if (denominator === 0) {
                throw new Error("Denominator cannot be zero!");
            }
            return numerator / denominator;
        }

        try {
            let result = divideNumbers(10, 0);
            console.log("Result: " + result);
        } catch (error) {
            console.error("An error occurred: " + error.message);
        }







        // Write a script that includes a try-catch block and a finally block. Log messages in the try, catch, and finally blocks to observe the execution flow.

        try {
            message
        } catch (error) {
            console.log(error.message);
        } finally {
            console.log('Finally Code Always Run');

        }







        // Create a custom error class that extends the built-in Error class. Throw an instance of this custom error in a function and handle it using a try-catch block.

        class CustomError extends Error {
            // name
            // constructor(message) {
            //     super(message);
            //     this.name = "CustomError";
            // }
        }

        function throwCustomError() {
            throw new CustomError("This is a custom error!");
        }

        try {
            throwCustomError();
        } catch (error) {
            if (error instanceof CustomError) {
                console.error("CUSTOM ERROR: " + error.message);
            } else {
                console.error("An error occurred: " + error.message);
            }
        }








        // Write a function that validates user input (e.g., checking if a string is not empty) and throws a custom error if the validation fails. Handle the custom error using a try-catch block.

        function validateUserInput(string) {
            if (string == '') {
                throw new Error("Input Field is Empty");
            }
            return string
        }

        const form = document.querySelector('#submit')

        form.addEventListener('submit', (e) => {
            e.preventDefault()

            const formData = new FormData(form)
            const data = Object.fromEntries(formData.entries())
            console.log(data);

            try {
                let result = validateUserInput(data.text)
                console.log("Result: " + result);
            } catch (error) {
                console.error("CUSTOM ERROR: " + error.message);
            }
        })







        // Create a promise that randomly resolves or rejects. Use .catch() to handle the rejection and log an appropriate message to the console.

        new Promise((resolve, reject) => {
            reject("First Promise rejected.");
        }).then(data => console.log(data))
            .catch(error => console.log('ERROR:', error));







        // Use try-catch within an async function to handle errors from a promise that randomly resolves or rejects, and log the error message.

        async function randomPromise() {
            return new Promise((resolve, reject) => {
                const randomNumber = Math.random()

                if (randomNumber > 0.5) {
                    resolve("Second Promise resolved successfully!");
                } else {
                    reject("Second Promise rejected...");
                }
            })
        }

        try {
            randomPromise().then(data => console.log(data))
        } catch (error) {
            console.log('CUSTOM ERROR', error.message);
        }







        // Use the fetch API to request data from an invalid URL and handle the error using .catch() . Log an appropriate error message to the console.

        fetch('https://dummyjson.com/producto') // 'https://dummyjson.com/products'
            .then(response => response.json())
            .then(data => console.log(data))
            .catch(error => console.log('CUSTOM ERROR', error.message));








        // use the fetch API to request data from an invalid URL within an async function and handle the error using try-catch. Log an appropriate error message.

        async function fetchData(URL) {
            try {
                const response = await fetch(URL);
                if (!response.ok) {
                    throw new Error('Network response was not ok');
                }
                const data = await response.json();
                console.log(data);
            } catch (error) {
                console.error('Failed to fetch data:', error.message);
            }
        }

        fetchData('https://dummyjson.com/producto'); // 'https://dummyjson.com/products'


    </script>
</body>

</html>